<?xml version="1.0" encoding="utf-8"?>
<!-- =================================================================================== -->
<!-- |    This document was autogenerated by xacro from m6.urdf.xacro                  | -->
<!-- |    EDITING THIS FILE BY HAND IS NOT RECOMMENDED                                 | -->
<!-- =================================================================================== -->
<robot name="m6">
  <!-- <link name="dummy">
  </link>

  <joint name="dummy_joint" type="fixed">
  <parent link="dummy"/>
  <child link="base_link"/>
  </joint> -->
  <link name="base_link">
    <inertial>
      <origin rpy="0 0 0 " xyz="-0.0028085 -0.0003448 0.0270705"/>
      <mass value="1.8476"/>
      <inertia ixx="0" ixy="0" ixz="0" iyy="0" iyz="0" izz="0"/>
    </inertial>
    <visual>
      <origin rpy="0 0 0" xyz="0 0 0"/>
      <geometry>
        <mesh filename="package://xMonsterCPG/meshes/M6_base_matt6_boxed_full.STL"/>
      </geometry>
      <material name="">
        <color rgba="0.39216 0.81961 0.93333 1"/>
      </material>
    </visual>
    <collision>
      <origin rpy="0.0 0.0 0.0" xyz="-0.020030 0.0 0.09"/>
      <geometry>
        <box size="0.261940 0.223 0.18"/>
      </geometry>
    </collision>
    <collision>
      <origin rpy="0.0 0.0 0.0" xyz="0.0 0.0 -0.0335"/>
      <geometry>
        <cylinder length="0.063" radius="0.0777"/>
      </geometry>
    </collision>
    <!-- Pipes below PC box -->
    <collision>
      <origin rpy="0.523583333333 1.57075 0.0" xyz="0.1209 -0.06985 -0.02"/>
      <geometry>
        <cylinder length="0.126" radius="0.015800"/>
      </geometry>
    </collision>
    <collision>
      <origin rpy="-0.523583333333 1.57075 0.0" xyz="0.1209 0.06985 -0.02"/>
      <geometry>
        <cylinder length="0.126" radius="0.015800"/>
      </geometry>
    </collision>
    <collision>
      <origin rpy="0.523583333333 1.57075 0.0" xyz="-0.1209 0.06985 -0.02"/>
      <geometry>
        <cylinder length="0.126" radius="0.015800"/>
      </geometry>
    </collision>
    <collision>
      <origin rpy="-0.523583333333 1.57075 0.0" xyz="-0.1209 -0.06985 -0.02"/>
      <geometry>
        <cylinder length="0.126" radius="0.015800"/>
      </geometry>
    </collision>
    <collision>
      <origin rpy="1.57075 1.57075 0.0" xyz="0.0 0.1147 -0.02"/>
      <geometry>
        <cylinder length="0.076" radius="0.015800"/>
      </geometry>
    </collision>
    <collision>
      <origin rpy="1.57075 1.57075 0.0" xyz="0.0 -0.1147 -0.02"/>
      <geometry>
        <cylinder length="0.076" radius="0.015800"/>
      </geometry>
    </collision>
    <!-- Boxes at the end of pipes -->
    <collision>
      <origin rpy="0.0 0.0 0.523583333333" xyz="0.20802 0.1201 -0.023"/>
      <geometry>
        <box size="0.073 0.075 0.046"/>
      </geometry>
    </collision>
    <collision>
      <origin rpy="0.0 0.0 -0.523583333333" xyz="0.20802 -0.1201 -0.023"/>
      <geometry>
        <box size="0.073 0.075 0.046"/>
      </geometry>
    </collision>
    <collision>
      <origin rpy="0.0 0.0 0.523583333333" xyz="-0.20802 -0.1201 -0.023"/>
      <geometry>
        <box size="0.073 0.075 0.046"/>
      </geometry>
    </collision>
    <collision>
      <origin rpy="0.0 0.0 -0.523583333333" xyz="-0.20802 0.1201 -0.023"/>
      <geometry>
        <box size="0.073 0.075 0.046"/>
      </geometry>
    </collision>
    <collision>
      <origin rpy="0.0 0.0 1.57075" xyz="0.0 0.1902 -0.023"/>
      <geometry>
        <box size="0.073 0.075 0.046"/>
      </geometry>
    </collision>
    <collision>
      <origin rpy="0.0 0.0 1.57075" xyz="0.0 -0.1902 -0.023"/>
      <geometry>
        <box size="0.073 0.075 0.046"/>
      </geometry>
    </collision>
  </link>
  <link name="camera_mount">
    <inertial>
      <origin rpy="0 0 0" xyz="-0.00036 0.10008 -0.02312"/>
      <mass value="0.0"/>
      <inertia ixx="0.0" ixy="0.0" ixz="0.0" iyy="0.0" iyz="0.0" izz="0.0"/>
    </inertial>
    <visual>
      <origin rpy="0 0 0" xyz="0 0 0"/>
      <geometry>
        <mesh filename="package://xMonsterCPG/meshes/camera_mount.STL" scale="1 1 1"/>
      </geometry>
      <material name="">
        <color rgba="0.79216 0.81961 0.93333 1"/>
      </material>
    </visual>
    <collision>
      <origin rpy="0 0 0" xyz="0 0 0"/>
      <geometry>
        <mesh filename="package://xMonsterCPG/meshes/camera_mount.STL" scale="1 1 1"/>
      </geometry>
    </collision>
  </link>
  <joint name="mount_joint" type="fixed">
    <origin rpy="1.57075 0 -1.57075" xyz="0.045 0 0.125"/>
    <parent link="base_link"/>
    <child link="camera_mount"/>
    <axis xyz="0 0 1"/>
    <limit effort="0" velocity="0"/>
  </joint>
  <!-- <joint name="camera_joint" type="fixed">
      <axis xyz="0 1 0" />
      <origin xyz="0 0 0" rpy="$0 0 0" />
      <parent link="camera_mount"/>
      <child link="camera_joint_link"/>
    </joint>
    <link name="camera_mount"/>
    <link name="camera_joint_link"/> -->
  <!--<xacro:include filename="$(find realsense_gazebo_plugin)/urdf/realsense-RS200.macro.xacro"/>-->
  <!--<xacro:include filename="$(find xMonsterCPG)/urdf/_d435.urdf.xacro"/>
    Create camera instance
    <xacro:realsense-rs200 prefix="left_" parent="base_link">
        <origin xyz="0.13 0.0 0.285" rpy="0 .13 0" />
    </xacro:realsense-rs200>-->
  <!-- <xacro:include filename="$(find realsense_gazebo_plugin)/urdf/realsense-RS200.macro.xacro"/>
    <xacro:realsense-rs200 prefix="realsense_" parent="base_link">
        <origin xyz="0.125 0 0.285" rpy="0 .33 0" />
    </xacro:realsense-rs200> -->
  <material name="realsense_d435_camera_aluminum">
    <color rgba="0.5 0.5 0.5 1"/>
  </material>
  <!-- camera body, with origin at bottom screw mount -->
  <joint name="realsense_d435_camera_joint" type="fixed">
    <origin rpy="0 0.2 0" xyz="0.1 0.0 0.3"/>
    <parent link="base_link"/>
    <child link="realsense_d435_camera_bottom_screw_frame"/>
  </joint>
  <link name="realsense_d435_camera_bottom_screw_frame"/>
  <joint name="realsense_d435_camera_link_joint" type="fixed">
    <origin rpy="0 0 0" xyz="0 0.0175 0.0125"/>
    <parent link="realsense_d435_camera_bottom_screw_frame"/>
    <child link="realsense_d435_camera_link"/>
  </joint>
  <link name="realsense_d435_camera_link">
    <visual>
      <origin rpy="1.57079632679 0 1.57079632679" xyz="0.0149 -0.0175 0"/>
      <geometry>
        <!-- <box size="${d435_cam_width} ${d435_cam_height} ${d435_cam_depth}"/> -->
        <!--<mesh filename="package://realsense2_description/meshes/d435.dae" />-->
        <mesh filename="package://xMonsterCPG/meshes/d435.dae"/>
        <!--<mesh filename="package://realsense2_description/meshes/d435/d435.dae" />-->
      </geometry>
      <material name="realsense_d435_camera_aluminum"/>
    </visual>
    <collision>
      <origin rpy="0 0 0" xyz="0 -0.0175 0"/>
      <geometry>
        <box size="0.02505 0.09 0.025"/>
      </geometry>
    </collision>
    <inertial>
      <!-- The following are not reliable values, and should not be used for modeling -->
      <mass value="0.564"/>
      <origin xyz="0 0 0"/>
      <inertia ixx="0.003881243" ixy="0.0" ixz="0.0" iyy="0.000498940" iyz="0.0" izz="0.003879257"/>
    </inertial>
  </link>
  <!-- camera depth joints and links -->
  <joint name="realsense_d435_camera_depth_joint" type="fixed">
    <origin rpy="0 0 0" xyz="0 0 0"/>
    <parent link="realsense_d435_camera_link"/>
    <child link="realsense_d435_camera_depth_frame"/>
  </joint>
  <link name="realsense_d435_camera_depth_frame"/>
  <joint name="realsense_d435_camera_depth_optical_joint" type="fixed">
    <origin rpy="-1.57079632679 0 -1.57079632679" xyz="0 0 0"/>
    <parent link="realsense_d435_camera_depth_frame"/>
    <child link="realsense_d435_camera_depth_optical_frame"/>
  </joint>
  <link name="realsense_d435_camera_depth_optical_frame"/>
  <!-- camera left IR joints and links -->
  <joint name="realsense_d435_camera_left_ir_joint" type="fixed">
    <origin rpy="0 0 0" xyz="0 0.0 0"/>
    <parent link="realsense_d435_camera_depth_frame"/>
    <child link="realsense_d435_camera_left_ir_frame"/>
  </joint>
  <link name="realsense_d435_camera_left_ir_frame"/>
  <joint name="realsense_d435_camera_left_ir_optical_joint" type="fixed">
    <origin rpy="-1.57079632679 0 -1.57079632679" xyz="0 0 0"/>
    <parent link="realsense_d435_camera_left_ir_frame"/>
    <child link="realsense_d435_camera_left_ir_optical_frame"/>
  </joint>
  <link name="realsense_d435_camera_left_ir_optical_frame"/>
  <!-- camera right IR joints and links -->
  <joint name="realsense_d435_camera_right_ir_joint" type="fixed">
    <origin rpy="0 0 0" xyz="0 -0.05 0"/>
    <parent link="realsense_d435_camera_depth_frame"/>
    <child link="realsense_d435_camera_right_ir_frame"/>
  </joint>
  <link name="realsense_d435_camera_right_ir_frame"/>
  <joint name="realsense_d435_camera_right_ir_optical_joint" type="fixed">
    <origin rpy="-1.57079632679 0 -1.57079632679" xyz="0 0 0"/>
    <parent link="realsense_d435_camera_right_ir_frame"/>
    <child link="realsense_d435_camera_right_ir_optical_frame"/>
  </joint>
  <link name="realsense_d435_camera_right_ir_optical_frame"/>
  <!-- camera color joints and links -->
  <joint name="realsense_d435_camera_color_joint" type="fixed">
    <origin rpy="0 0 0" xyz="0 0 0"/>
    <parent link="realsense_d435_camera_depth_frame"/>
    <child link="realsense_d435_camera_color_frame"/>
  </joint>
  <link name="realsense_d435_camera_color_frame"/>
  <joint name="realsense_d435_camera_color_optical_joint" type="fixed">
    <origin rpy="-1.57079632679 0 -1.57079632679" xyz="0 0 0"/>
    <parent link="realsense_d435_camera_color_frame"/>
    <child link="realsense_d435_camera_color_optical_frame"/>
  </joint>
  <link name="realsense_d435_camera_color_optical_frame"/>
  <gazebo reference="realsense_d435_camera_link">
    <self_collide>0</self_collide>
    <enable_wind>0</enable_wind>
    <kinematic>0</kinematic>
    <gravity>1</gravity>
    <!--<mu>1</mu>-->
    <mu2>1</mu2>
    <fdir1>0 0 0</fdir1>
    <!--<slip1>0</slip1>
      <slip2>0</slip2>-->
    <kp>1e+13</kp>
    <kd>1</kd>
    <!--<max_vel>0.01</max_vel>
      <min_depth>0</min_depth>-->
    <sensor name="realsense_d435_cameracolor" type="camera">
      <camera name="realsense_d435_camera">
        <horizontal_fov>1.21125850088</horizontal_fov>
        <image>
          <width>1920</width>
          <height>1080</height>
          <format>RGB_INT8</format>
        </image>
        <clip>
          <near>0.1</near>
          <far>100</far>
        </clip>
        <noise>
          <type>gaussian</type>
          <mean>0.0</mean>
          <stddev>0.007</stddev>
        </noise>
      </camera>
      <always_on>1</always_on>
      <update_rate>100</update_rate>
      <visualize>0</visualize>
    </sensor>
    <sensor name="realsense_d435_cameraired1" type="camera">
      <camera name="realsense_d435_camera">
        <horizontal_fov>1.4870205227</horizontal_fov>
        <image>
          <width>1280</width>
          <height>720</height>
          <format>L_INT8</format>
        </image>
        <clip>
          <near>0.1</near>
          <far>100</far>
        </clip>
        <noise>
          <type>gaussian</type>
          <mean>0.0</mean>
          <stddev>0.05</stddev>
        </noise>
      </camera>
      <always_on>1</always_on>
      <update_rate>100</update_rate>
      <visualize>0</visualize>
    </sensor>
    <sensor name="realsense_d435_cameraired2" type="camera">
      <camera name="realsense_d435_camera">
        <horizontal_fov>1.4870205227</horizontal_fov>
        <image>
          <width>1280</width>
          <height>720</height>
          <format>L_INT8</format>
        </image>
        <clip>
          <near>0.1</near>
          <far>100</far>
        </clip>
        <noise>
          <type>gaussian</type>
          <mean>0.0</mean>
          <stddev>0.05</stddev>
        </noise>
      </camera>
      <always_on>1</always_on>
      <update_rate>100</update_rate>
      <visualize>0</visualize>
    </sensor>
    <sensor name="realsense_d435_cameradepth" type="depth">
      <camera name="realsense_d435_camera">
        <horizontal_fov>1.21125850088</horizontal_fov>
        <image>
          <width>1080</width>
          <height>720</height>
        </image>
        <clip>
          <near>0.1</near>
          <far>100</far>
        </clip>
        <noise>
          <type>gaussian</type>
          <mean>0.0</mean>
          <stddev>0.100</stddev>
        </noise>
      </camera>
      <always_on>1</always_on>
      <update_rate>100</update_rate>
      <visualize>0</visualize>
    </sensor>
  </gazebo>
  <gazebo>
    <plugin filename="librealsense_gazebo_plugin.so" name="realsense_d435">
      <prefix>realsense_d435_camera</prefix>
      <depthUpdateRate>100</depthUpdateRate>
      <colorUpdateRate>100</colorUpdateRate>
      <infraredUpdateRate>60.0</infraredUpdateRate>
      <depthTopicName>depth/image_raw</depthTopicName>
      <depthCameraInfoTopicName>depth/camera_info</depthCameraInfoTopicName>
      <colorTopicName>color/image_raw</colorTopicName>
      <colorCameraInfoTopicName>color/camera_info</colorCameraInfoTopicName>
      <infrared1TopicName>infra1/image_raw</infrared1TopicName>
      <infrared1CameraInfoTopicName>infra1/camera_info</infrared1CameraInfoTopicName>
      <infrared2TopicName>infra2/image_raw</infrared2TopicName>
      <infrared2CameraInfoTopicName>infra2/camera_info</infrared2CameraInfoTopicName>
      <colorOpticalframeName>realsense_d435_camera_color_optical_frame</colorOpticalframeName>
      <depthOpticalframeName>realsense_d435_camera_depth_optical_frame</depthOpticalframeName>
      <infrared1OpticalframeName>realsense_d435_camera_left_ir_optical_frame</infrared1OpticalframeName>
      <infrared2OpticalframeName>realsense_d435_camera_right_ir_optical_frame</infrared2OpticalframeName>
      <rangeMinDepth>0.2</rangeMinDepth>
      <rangeMaxDepth>3.0</rangeMaxDepth>
      <pointCloud>true</pointCloud>
      <pointCloudTopicName>depth/points</pointCloudTopicName>
      <pointCloudCutoff>0.2</pointCloudCutoff>
      <pointCloudCutoffMax>3</pointCloudCutoffMax>
    </plugin>
  </gazebo>
  <gazebo>
    <plugin filename="libgazebo_ros_imu.so" name="imu_plugin">
      <alwaysOn>true</alwaysOn>
      <bodyName>base_link</bodyName>
      <topicName>camera_imu</topicName>
      <serviceName>imu_service</serviceName>
      <gaussianNoise>0.0</gaussianNoise>
      <updateRate>100.0</updateRate>
    </plugin>
  </gazebo>
  <link name="base1__INPUT_INTERFACE">
    <inertial>
      <origin rpy="0 0 0" xyz="0.015005 0.001775 0.015011"/>
      <mass value="1.2804"/>
      <inertia ixx="0.000533112547871023" ixy="8.52907138161489E-05" ixz="6.73224445510202E-07" iyy="0.000959826064510336" iyz="8.0840859065961E-07" izz="0.00130175668733721"/>
    </inertial>
    <visual>
      <origin rpy="0 0 0" xyz="0 0 0.015"/>
      <geometry>
        <mesh filename="package://xMonsterCPG/meshes/M6_base_motor.STL"/>
      </geometry>
      <material name="">
        <color rgba="0.79216 0.81961 0.93333 1"/>
      </material>
    </visual>
    <collision>
      <!--origin
          xyz="0 0 0.015"
          rpy="0 0 0" />
        <geometry>
          <mesh
            filename="package://xMonsterCPG/meshes/boxed_meshes/base_motor.STL" />
        </geometry-->
      <origin rpy="0 0 0" xyz="0.019940 0.001750 0.015525"/>
      <geometry>
        <box size="0.106400 0.069500 0.031050"/>
      </geometry>
    </collision>
  </link>
  <joint name="leg1__OUTPUT_INTERFACE" type="fixed">
    <origin rpy="0 0 3.66508333333" xyz="0.205681 0.11875 0"/>
    <parent link="base_link"/>
    <child link="base1__INPUT_INTERFACE"/>
    <axis xyz="0 0 1"/>
    <limit effort="0" velocity="0"/>
  </joint>
  <link name="shoulder1__INPUT_INTERFACE">
    <inertial>
      <origin rpy="0 0 0" xyz="-0.012554 -0.0090693 0.0503697"/>
      <mass value="1.4679"/>
      <inertia ixx="0.00085304" ixy="-4.463E-05" ixz="4.178E-05" iyy="0.0016596" iyz="4.4E-06" izz="0.00113592"/>
    </inertial>
    <visual>
      <origin rpy="0 0 0" xyz="0 0 0"/>
      <geometry>
        <mesh filename="package://xMonsterCPG/meshes/M6_left_link1_red.STL"/>
      </geometry>
      <material name="">
        <color rgba="0.75294 0.75294 0.75294 1"/>
      </material>
    </visual>
    <collision>
      <!--origin
          xyz="0 0 0"
          rpy="0 0 0" />
        <geometry>
          <mesh
            filename="package://xMonsterCPG/meshes/boxed_meshes/left_link1_red.STL" />
        </geometry-->
      <origin rpy="0 0 0" xyz="-0.019070 -0.014470 0.052500"/>
      <geometry>
        <box size="0.108140 0.04500 0.104000"/>
      </geometry>
    </collision>
  </link>
  <joint name="base1" type="revolute">
    <origin rpy="0 0 3.1415" xyz="0 0 0.03105"/>
    <parent link="base1__INPUT_INTERFACE"/>
    <child link="shoulder1__INPUT_INTERFACE"/>
    <axis xyz="0 0 1"/>
    <dynamics damping=".1" friction="0.2"/>
    <limit effort="30.0" lower="-1.57075" upper="1.57075" velocity="2.208932"/>
  </joint>
  <transmission name="base1_trans">
    <type>transmission_interface/SimpleTransmission</type>
    <joint name="base1">
      <hardwareInterface>hardware_interface/EffortJointInterface</hardwareInterface>
    </joint>
    <actuator name="base1_motor">
      <hardwareInterface>hardware_interface/EffortJointInterface</hardwareInterface>
      <mechanicalReduction>300</mechanicalReduction>
    </actuator>
  </transmission>
  <link name="elbow1__INPUT_INTERFACE">
    <inertial>
      <origin rpy="0 0 0" xyz="0.27885723 0.00143862 -0.00919708"/>
      <mass value="1.58985"/>
      <inertia ixx="0.00087813" ixy="-2.653E-05" ixz="-0.00101493" iyy="0.01121522" iyz="-1.36E-05" izz="0.01137087"/>
    </inertial>
    <visual>
      <origin rpy="0 0 0" xyz="0 0 0"/>
      <geometry>
        <mesh filename="package://xMonsterCPG/meshes/M6_link2_red.STL"/>
      </geometry>
      <material name="">
        <color rgba="0.75294 0.75294 0.75294 1"/>
      </material>
    </visual>
    <collision>
      <!--origin
          xyz="0 0 0"
          rpy="0 0 0" />
        <geometry>
          <mesh
            filename="package://xMonsterCPG/meshes/boxed_meshes/link2_red.STL" />
        </geometry-->
      <origin rpy="0 0 0" xyz="0.005750 0.0 0.018750"/>
      <geometry>
        <box size="0.05950 0.04800 0.037500"/>
      </geometry>
    </collision>
    <collision>
      <origin rpy="0 1.57075 0" xyz="0.159500 0.0 0.02"/>
      <geometry>
        <cylinder length="0.246" radius="0.015811"/>
      </geometry>
    </collision>
    <collision>
      <origin rpy="0 0 0" xyz="0.317750 0.0 0.01875"/>
      <geometry>
        <box size="0.06850 0.06500 0.037500"/>
      </geometry>
    </collision>
    <collision>
      <origin rpy="0.0 0.0 0.0" xyz="0.299560 0.001750 -0.015520"/>
      <geometry>
        <box size="0.106400 0.069500 0.030050"/>
      </geometry>
    </collision>
  </link>
  <joint name="shoulder1" type="revolute">
    <origin rpy="-1.57075 0 0" xyz="0 0.00855 0.055"/>
    <parent link="shoulder1__INPUT_INTERFACE"/>
    <child link="elbow1__INPUT_INTERFACE"/>
    <axis xyz="0 0 1"/>
    <dynamics damping=".1" friction="0.2"/>
    <limit effort="30.0" lower="-1.57075" upper="1.57075" velocity="2.208932"/>
  </joint>
  <transmission name="shoulder1_trans">
    <type>transmission_interface/SimpleTransmission</type>
    <joint name="shoulder1">
      <hardwareInterface>hardware_interface/EffortJointInterface</hardwareInterface>
    </joint>
    <actuator name="shoulder1_motor">
      <hardwareInterface>hardware_interface/EffortJointInterface</hardwareInterface>
      <mechanicalReduction>300</mechanicalReduction>
    </actuator>
  </transmission>
  <link name="leg1__LAST_LINK">
    <inertial>
      <origin rpy="0 0 0" xyz="0.12121923 0 0.01723596"/>
      <mass value="0.229433"/>
      <inertia ixx="7.471E-05" ixy="0" ixz="7.798E-05" iyy="0.00331684" iyz="0" izz="0.0033262"/>
    </inertial>
    <visual>
      <origin rpy="0 0 0" xyz="0 0 0"/>
      <geometry>
        <mesh filename="package://xMonsterCPG/meshes/M6_link3_red.STL"/>
      </geometry>
      <material name="">
        <color rgba="0.75294 0.75294 0.75294 1"/>
      </material>
    </visual>
    <!--collision>
        <origin
          xyz="0 0 0"
          rpy="0 0 0" />
        <geometry>
          <mesh
            filename="package://xMonsterCPG/meshes/boxed_meshes/link3_red.STL" />
        </geometry>
      </collision-->
    <collision>
      <origin rpy="0 0 0" xyz="0.00575 0.0 0.0185"/>
      <geometry>
        <box size="0.05850 0.04800 0.03650"/>
      </geometry>
    </collision>
    <collision>
      <origin rpy="0.0 1.57075 0.0" xyz="0.15125 0.000 0.020"/>
      <geometry>
        <cylinder length="0.230500" radius="0.015811"/>
      </geometry>
    </collision>
    <collision>
      <origin rpy="0.0 0.0 0.0" xyz="0.28950 0.00 0.02"/>
      <geometry>
        <box size="0.045000 0.047030 0.047030"/>
      </geometry>
    </collision>
  </link>
  <joint name="elbow1" type="revolute">
    <origin rpy="3.1415 0 0" xyz="0.3195 0 -0.03105"/>
    <parent link="elbow1__INPUT_INTERFACE"/>
    <child link="leg1__LAST_LINK"/>
    <axis xyz="0 0 1"/>
    <dynamics damping=".1" friction="0.2"/>
    <limit effort="30.0" lower="-3.1415" upper="3.1415" velocity="2.208932"/>
  </joint>
  <transmission name="elbow1_trans">
    <type>transmission_interface/SimpleTransmission</type>
    <joint name="elbow1">
      <hardwareInterface>hardware_interface/EffortJointInterface</hardwareInterface>
    </joint>
    <actuator name="elbow1_motor">
      <hardwareInterface>hardware_interface/EffortJointInterface</hardwareInterface>
      <mechanicalReduction>300</mechanicalReduction>
    </actuator>
  </transmission>
  <link name="leg1__FOOT">
    <inertial>
      <origin rpy="0 0 0" xyz="0 0 0"/>
      <mass value="0"/>
      <inertia ixx="0" ixy="0" ixz="0" iyy="0" iyz="0" izz="0"/>
    </inertial>
  </link>
  <joint name="leg1__FOOT_INTERFACE" type="fixed">
    <origin rpy="0 0 0" xyz="0.31 0 0.02"/>
    <parent link="leg1__LAST_LINK"/>
    <child link="leg1__FOOT"/>
    <axis xyz="0 0 1"/>
    <limit effort="0" velocity="0"/>
  </joint>
  <link name="base3__INPUT_INTERFACE">
    <inertial>
      <origin rpy="0 0 0" xyz="0.015005 0.001775 0.015011"/>
      <mass value="1.2804"/>
      <inertia ixx="0.000533112547871023" ixy="8.52907138161489E-05" ixz="6.73224445510202E-07" iyy="0.000959826064510336" iyz="8.0840859065961E-07" izz="0.00130175668733721"/>
    </inertial>
    <visual>
      <origin rpy="0 0 0" xyz="0 0 0.015"/>
      <geometry>
        <mesh filename="package://xMonsterCPG/meshes/M6_base_motor.STL"/>
      </geometry>
      <material name="">
        <color rgba="0.79216 0.81961 0.93333 1"/>
      </material>
    </visual>
    <collision>
      <!--origin
          xyz="0 0 0.015"
          rpy="0 0 0" />
        <geometry>
          <mesh
            filename="package://xMonsterCPG/meshes/boxed_meshes/base_motor.STL" />
        </geometry-->
      <origin rpy="0 0 0" xyz="0.019940 0.001750 0.015525"/>
      <geometry>
        <box size="0.106400 0.069500 0.031050"/>
      </geometry>
    </collision>
  </link>
  <joint name="leg3__OUTPUT_INTERFACE" type="fixed">
    <origin rpy="0 0 4.71225" xyz="0 0.1875 0"/>
    <parent link="base_link"/>
    <child link="base3__INPUT_INTERFACE"/>
    <axis xyz="0 0 1"/>
    <limit effort="0" velocity="0"/>
  </joint>
  <link name="shoulder3__INPUT_INTERFACE">
    <inertial>
      <origin rpy="0 0 0" xyz="-0.012554 -0.0090693 0.0503697"/>
      <mass value="1.4679"/>
      <inertia ixx="0.00085304" ixy="-4.463E-05" ixz="4.178E-05" iyy="0.0016596" iyz="4.4E-06" izz="0.00113592"/>
    </inertial>
    <visual>
      <origin rpy="0 0 0" xyz="0 0 0"/>
      <geometry>
        <mesh filename="package://xMonsterCPG/meshes/M6_left_link1_red.STL"/>
      </geometry>
      <material name="">
        <color rgba="0.75294 0.75294 0.75294 1"/>
      </material>
    </visual>
    <collision>
      <!--origin
          xyz="0 0 0"
          rpy="0 0 0" />
        <geometry>
          <mesh
            filename="package://xMonsterCPG/meshes/boxed_meshes/left_link1_red.STL" />
        </geometry-->
      <origin rpy="0 0 0" xyz="-0.019070 -0.014470 0.052500"/>
      <geometry>
        <box size="0.108140 0.04500 0.104000"/>
      </geometry>
    </collision>
  </link>
  <joint name="base3" type="revolute">
    <origin rpy="0 0 3.1415" xyz="0 0 0.03105"/>
    <parent link="base3__INPUT_INTERFACE"/>
    <child link="shoulder3__INPUT_INTERFACE"/>
    <axis xyz="0 0 1"/>
    <dynamics damping=".1" friction="0.2"/>
    <limit effort="30.0" lower="-1.57075" upper="1.57075" velocity="2.208932"/>
  </joint>
  <transmission name="base3_trans">
    <type>transmission_interface/SimpleTransmission</type>
    <joint name="base3">
      <hardwareInterface>hardware_interface/EffortJointInterface</hardwareInterface>
    </joint>
    <actuator name="base3_motor">
      <hardwareInterface>hardware_interface/EffortJointInterface</hardwareInterface>
      <mechanicalReduction>300</mechanicalReduction>
    </actuator>
  </transmission>
  <link name="elbow3__INPUT_INTERFACE">
    <inertial>
      <origin rpy="0 0 0" xyz="0.27885723 0.00143862 -0.00919708"/>
      <mass value="1.58985"/>
      <inertia ixx="0.00087813" ixy="-2.653E-05" ixz="-0.00101493" iyy="0.01121522" iyz="-1.36E-05" izz="0.01137087"/>
    </inertial>
    <visual>
      <origin rpy="0 0 0" xyz="0 0 0"/>
      <geometry>
        <mesh filename="package://xMonsterCPG/meshes/M6_link2_red.STL"/>
      </geometry>
      <material name="">
        <color rgba="0.75294 0.75294 0.75294 1"/>
      </material>
    </visual>
    <collision>
      <!--origin
          xyz="0 0 0"
          rpy="0 0 0" />
        <geometry>
          <mesh
            filename="package://xMonsterCPG/meshes/boxed_meshes/link2_red.STL" />
        </geometry-->
      <origin rpy="0 0 0" xyz="0.005750 0.0 0.018750"/>
      <geometry>
        <box size="0.05950 0.04800 0.037500"/>
      </geometry>
    </collision>
    <collision>
      <origin rpy="0 1.57075 0" xyz="0.159500 0.0 0.02"/>
      <geometry>
        <cylinder length="0.246" radius="0.015811"/>
      </geometry>
    </collision>
    <collision>
      <origin rpy="0 0 0" xyz="0.317750 0.0 0.01875"/>
      <geometry>
        <box size="0.06850 0.06500 0.037500"/>
      </geometry>
    </collision>
    <collision>
      <origin rpy="0.0 0.0 0.0" xyz="0.299560 0.001750 -0.015520"/>
      <geometry>
        <box size="0.106400 0.069500 0.030050"/>
      </geometry>
    </collision>
  </link>
  <joint name="shoulder3" type="revolute">
    <origin rpy="-1.57075 0 0" xyz="0 0.00855 0.055"/>
    <parent link="shoulder3__INPUT_INTERFACE"/>
    <child link="elbow3__INPUT_INTERFACE"/>
    <axis xyz="0 0 1"/>
    <dynamics damping=".1" friction="0.2"/>
    <limit effort="30.0" lower="-1.57075" upper="1.57075" velocity="2.208932"/>
  </joint>
  <transmission name="shoulder3_trans">
    <type>transmission_interface/SimpleTransmission</type>
    <joint name="shoulder3">
      <hardwareInterface>hardware_interface/EffortJointInterface</hardwareInterface>
    </joint>
    <actuator name="shoulder3_motor">
      <hardwareInterface>hardware_interface/EffortJointInterface</hardwareInterface>
      <mechanicalReduction>300</mechanicalReduction>
    </actuator>
  </transmission>
  <link name="leg3__LAST_LINK">
    <inertial>
      <origin rpy="0 0 0" xyz="0.12121923 0 0.01723596"/>
      <mass value="0.229433"/>
      <inertia ixx="7.471E-05" ixy="0" ixz="7.798E-05" iyy="0.00331684" iyz="0" izz="0.0033262"/>
    </inertial>
    <visual>
      <origin rpy="0 0 0" xyz="0 0 0"/>
      <geometry>
        <mesh filename="package://xMonsterCPG/meshes/M6_link3_red.STL"/>
      </geometry>
      <material name="">
        <color rgba="0.75294 0.75294 0.75294 1"/>
      </material>
    </visual>
    <!--collision>
        <origin
          xyz="0 0 0"
          rpy="0 0 0" />
        <geometry>
          <mesh
            filename="package://xMonsterCPG/meshes/boxed_meshes/link3_red.STL" />
        </geometry>
      </collision-->
    <collision>
      <origin rpy="0 0 0" xyz="0.00575 0.0 0.0185"/>
      <geometry>
        <box size="0.05850 0.04800 0.03650"/>
      </geometry>
    </collision>
    <collision>
      <origin rpy="0.0 1.57075 0.0" xyz="0.15125 0.000 0.020"/>
      <geometry>
        <cylinder length="0.230500" radius="0.015811"/>
      </geometry>
    </collision>
    <collision>
      <origin rpy="0.0 0.0 0.0" xyz="0.28950 0.00 0.02"/>
      <geometry>
        <box size="0.045000 0.047030 0.047030"/>
      </geometry>
    </collision>
  </link>
  <joint name="elbow3" type="revolute">
    <origin rpy="3.1415 0 0" xyz="0.3195 0 -0.03105"/>
    <parent link="elbow3__INPUT_INTERFACE"/>
    <child link="leg3__LAST_LINK"/>
    <axis xyz="0 0 1"/>
    <dynamics damping=".1" friction="0.2"/>
    <limit effort="30.0" lower="-3.1415" upper="3.1415" velocity="2.208932"/>
  </joint>
  <transmission name="elbow3_trans">
    <type>transmission_interface/SimpleTransmission</type>
    <joint name="elbow3">
      <hardwareInterface>hardware_interface/EffortJointInterface</hardwareInterface>
    </joint>
    <actuator name="elbow3_motor">
      <hardwareInterface>hardware_interface/EffortJointInterface</hardwareInterface>
      <mechanicalReduction>300</mechanicalReduction>
    </actuator>
  </transmission>
  <link name="leg3__FOOT">
    <inertial>
      <origin rpy="0 0 0" xyz="0 0 0"/>
      <mass value="0"/>
      <inertia ixx="0" ixy="0" ixz="0" iyy="0" iyz="0" izz="0"/>
    </inertial>
  </link>
  <joint name="leg3__FOOT_INTERFACE" type="fixed">
    <origin rpy="0 0 0" xyz="0.31 0 0.02"/>
    <parent link="leg3__LAST_LINK"/>
    <child link="leg3__FOOT"/>
    <axis xyz="0 0 1"/>
    <limit effort="0" velocity="0"/>
  </joint>
  <link name="base5__INPUT_INTERFACE">
    <inertial>
      <origin rpy="0 0 0" xyz="0.015005 0.001775 0.015011"/>
      <mass value="1.2804"/>
      <inertia ixx="0.000533112547871023" ixy="8.52907138161489E-05" ixz="6.73224445510202E-07" iyy="0.000959826064510336" iyz="8.0840859065961E-07" izz="0.00130175668733721"/>
    </inertial>
    <visual>
      <origin rpy="0 0 0" xyz="0 0 0.015"/>
      <geometry>
        <mesh filename="package://xMonsterCPG/meshes/M6_base_motor.STL"/>
      </geometry>
      <material name="">
        <color rgba="0.79216 0.81961 0.93333 1"/>
      </material>
    </visual>
    <collision>
      <!--origin
          xyz="0 0 0.015"
          rpy="0 0 0" />
        <geometry>
          <mesh
            filename="package://xMonsterCPG/meshes/boxed_meshes/base_motor.STL" />
        </geometry-->
      <origin rpy="0 0 0" xyz="0.019940 0.001750 0.015525"/>
      <geometry>
        <box size="0.106400 0.069500 0.031050"/>
      </geometry>
    </collision>
  </link>
  <joint name="leg5__OUTPUT_INTERFACE" type="fixed">
    <origin rpy="0 0 5.75941666667" xyz="-0.205681 0.11875 0"/>
    <parent link="base_link"/>
    <child link="base5__INPUT_INTERFACE"/>
    <axis xyz="0 0 1"/>
    <limit effort="0" velocity="0"/>
  </joint>
  <link name="shoulder5__INPUT_INTERFACE">
    <inertial>
      <origin rpy="0 0 0" xyz="-0.012554 -0.0090693 0.0503697"/>
      <mass value="1.4679"/>
      <inertia ixx="0.00085304" ixy="-4.463E-05" ixz="4.178E-05" iyy="0.0016596" iyz="4.4E-06" izz="0.00113592"/>
    </inertial>
    <visual>
      <origin rpy="0 0 0" xyz="0 0 0"/>
      <geometry>
        <mesh filename="package://xMonsterCPG/meshes/M6_left_link1_red.STL"/>
      </geometry>
      <material name="">
        <color rgba="0.75294 0.75294 0.75294 1"/>
      </material>
    </visual>
    <collision>
      <!--origin
          xyz="0 0 0"
          rpy="0 0 0" />
        <geometry>
          <mesh
            filename="package://xMonsterCPG/meshes/boxed_meshes/left_link1_red.STL" />
        </geometry-->
      <origin rpy="0 0 0" xyz="-0.019070 -0.014470 0.052500"/>
      <geometry>
        <box size="0.108140 0.04500 0.104000"/>
      </geometry>
    </collision>
  </link>
  <joint name="base5" type="revolute">
    <origin rpy="0 0 3.1415" xyz="0 0 0.03105"/>
    <parent link="base5__INPUT_INTERFACE"/>
    <child link="shoulder5__INPUT_INTERFACE"/>
    <axis xyz="0 0 1"/>
    <dynamics damping=".1" friction="0.2"/>
    <limit effort="30.0" lower="-1.57075" upper="1.57075" velocity="2.208932"/>
  </joint>
  <transmission name="base5_trans">
    <type>transmission_interface/SimpleTransmission</type>
    <joint name="base5">
      <hardwareInterface>hardware_interface/EffortJointInterface</hardwareInterface>
    </joint>
    <actuator name="base5_motor">
      <hardwareInterface>hardware_interface/EffortJointInterface</hardwareInterface>
      <mechanicalReduction>300</mechanicalReduction>
    </actuator>
  </transmission>
  <link name="elbow5__INPUT_INTERFACE">
    <inertial>
      <origin rpy="0 0 0" xyz="0.27885723 0.00143862 -0.00919708"/>
      <mass value="1.58985"/>
      <inertia ixx="0.00087813" ixy="-2.653E-05" ixz="-0.00101493" iyy="0.01121522" iyz="-1.36E-05" izz="0.01137087"/>
    </inertial>
    <visual>
      <origin rpy="0 0 0" xyz="0 0 0"/>
      <geometry>
        <mesh filename="package://xMonsterCPG/meshes/M6_link2_red.STL"/>
      </geometry>
      <material name="">
        <color rgba="0.75294 0.75294 0.75294 1"/>
      </material>
    </visual>
    <collision>
      <!--origin
          xyz="0 0 0"
          rpy="0 0 0" />
        <geometry>
          <mesh
            filename="package://xMonsterCPG/meshes/boxed_meshes/link2_red.STL" />
        </geometry-->
      <origin rpy="0 0 0" xyz="0.005750 0.0 0.018750"/>
      <geometry>
        <box size="0.05950 0.04800 0.037500"/>
      </geometry>
    </collision>
    <collision>
      <origin rpy="0 1.57075 0" xyz="0.159500 0.0 0.02"/>
      <geometry>
        <cylinder length="0.246" radius="0.015811"/>
      </geometry>
    </collision>
    <collision>
      <origin rpy="0 0 0" xyz="0.317750 0.0 0.01875"/>
      <geometry>
        <box size="0.06850 0.06500 0.037500"/>
      </geometry>
    </collision>
    <collision>
      <origin rpy="0.0 0.0 0.0" xyz="0.299560 0.001750 -0.015520"/>
      <geometry>
        <box size="0.106400 0.069500 0.030050"/>
      </geometry>
    </collision>
  </link>
  <joint name="shoulder5" type="revolute">
    <origin rpy="-1.57075 0 0" xyz="0 0.00855 0.055"/>
    <parent link="shoulder5__INPUT_INTERFACE"/>
    <child link="elbow5__INPUT_INTERFACE"/>
    <axis xyz="0 0 1"/>
    <dynamics damping=".1" friction="0.2"/>
    <limit effort="30.0" lower="-1.57075" upper="1.57075" velocity="2.208932"/>
  </joint>
  <transmission name="shoulder5_trans">
    <type>transmission_interface/SimpleTransmission</type>
    <joint name="shoulder5">
      <hardwareInterface>hardware_interface/EffortJointInterface</hardwareInterface>
    </joint>
    <actuator name="shoulder5_motor">
      <hardwareInterface>hardware_interface/EffortJointInterface</hardwareInterface>
      <mechanicalReduction>300</mechanicalReduction>
    </actuator>
  </transmission>
  <link name="leg5__LAST_LINK">
    <inertial>
      <origin rpy="0 0 0" xyz="0.12121923 0 0.01723596"/>
      <mass value="0.229433"/>
      <inertia ixx="7.471E-05" ixy="0" ixz="7.798E-05" iyy="0.00331684" iyz="0" izz="0.0033262"/>
    </inertial>
    <visual>
      <origin rpy="0 0 0" xyz="0 0 0"/>
      <geometry>
        <mesh filename="package://xMonsterCPG/meshes/M6_link3_red.STL"/>
      </geometry>
      <material name="">
        <color rgba="0.75294 0.75294 0.75294 1"/>
      </material>
    </visual>
    <!--collision>
        <origin
          xyz="0 0 0"
          rpy="0 0 0" />
        <geometry>
          <mesh
            filename="package://xMonsterCPG/meshes/boxed_meshes/link3_red.STL" />
        </geometry>
      </collision-->
    <collision>
      <origin rpy="0 0 0" xyz="0.00575 0.0 0.0185"/>
      <geometry>
        <box size="0.05850 0.04800 0.03650"/>
      </geometry>
    </collision>
    <collision>
      <origin rpy="0.0 1.57075 0.0" xyz="0.15125 0.000 0.020"/>
      <geometry>
        <cylinder length="0.230500" radius="0.015811"/>
      </geometry>
    </collision>
    <collision>
      <origin rpy="0.0 0.0 0.0" xyz="0.28950 0.00 0.02"/>
      <geometry>
        <box size="0.045000 0.047030 0.047030"/>
      </geometry>
    </collision>
  </link>
  <joint name="elbow5" type="revolute">
    <origin rpy="3.1415 0 0" xyz="0.3195 0 -0.03105"/>
    <parent link="elbow5__INPUT_INTERFACE"/>
    <child link="leg5__LAST_LINK"/>
    <axis xyz="0 0 1"/>
    <dynamics damping=".1" friction="0.2"/>
    <limit effort="30.0" lower="-3.1415" upper="3.1415" velocity="2.208932"/>
  </joint>
  <transmission name="elbow5_trans">
    <type>transmission_interface/SimpleTransmission</type>
    <joint name="elbow5">
      <hardwareInterface>hardware_interface/EffortJointInterface</hardwareInterface>
    </joint>
    <actuator name="elbow5_motor">
      <hardwareInterface>hardware_interface/EffortJointInterface</hardwareInterface>
      <mechanicalReduction>300</mechanicalReduction>
    </actuator>
  </transmission>
  <link name="leg5__FOOT">
    <inertial>
      <origin rpy="0 0 0" xyz="0 0 0"/>
      <mass value="0"/>
      <inertia ixx="0" ixy="0" ixz="0" iyy="0" iyz="0" izz="0"/>
    </inertial>
  </link>
  <joint name="leg5__FOOT_INTERFACE" type="fixed">
    <origin rpy="0 0 0" xyz="0.31 0 0.02"/>
    <parent link="leg5__LAST_LINK"/>
    <child link="leg5__FOOT"/>
    <axis xyz="0 0 1"/>
    <limit effort="0" velocity="0"/>
  </joint>
  <link name="base2__INPUT_INTERFACE">
    <inertial>
      <origin rpy="0 0 0" xyz="0.015005 0.001775 0.015011"/>
      <mass value="1.2804"/>
      <inertia ixx="0.000533112547871023" ixy="8.52907138161489E-05" ixz="6.73224445510202E-07" iyy="0.000959826064510336" iyz="8.0840859065961E-07" izz="0.00130175668733721"/>
    </inertial>
    <visual>
      <origin rpy="0 0 0" xyz="0 0 0.015"/>
      <geometry>
        <mesh filename="package://xMonsterCPG/meshes/M6_base_motor.STL"/>
      </geometry>
      <material name="">
        <color rgba="0.79216 0.81961 0.93333 1"/>
      </material>
    </visual>
    <collision>
      <!--origin
          xyz="0 0 0.015"
          rpy="0 0 0" />
        <geometry>
          <mesh
            filename="package://xMonsterCPG/meshes/boxed_meshes/base_motor.STL" />
        </geometry-->
      <origin rpy="0 0 0" xyz="0.019940 0.001750 0.015525"/>
      <geometry>
        <box size="0.106400 0.069500 0.031050"/>
      </geometry>
    </collision>
  </link>
  <joint name="leg2__OUTPUT_INTERFACE" type="fixed">
    <origin rpy="0 0 2.61791666667" xyz="0.205681 -0.11875 0"/>
    <parent link="base_link"/>
    <child link="base2__INPUT_INTERFACE"/>
    <axis xyz="0 0 1"/>
    <limit effort="0" velocity="0"/>
  </joint>
  <link name="shoulder2__INPUT_INTERFACE">
    <inertial>
      <origin rpy="0 0 0" xyz="-0.012554 -0.0090693 -0.0503697"/>
      <mass value="1.4679"/>
      <inertia ixx="0.00085304" ixy="-4.463E-05" ixz="-4.178E-05" iyy="0.0016596" iyz="-4.4E-06" izz="0.00113592"/>
    </inertial>
    <visual>
      <origin rpy="0 0 0" xyz="0 0 0"/>
      <geometry>
        <mesh filename="package://xMonsterCPG/meshes/M6_right_link1_red.STL"/>
      </geometry>
      <material name="">
        <color rgba="0.75294 0.75294 0.75294 1"/>
      </material>
    </visual>
    <collision>
      <!--origin
          xyz="0 0 0"
          rpy="0 0 0" />
        <geometry>
          <mesh
            filename="package://xMonsterCPG/meshes/boxed_meshes/right_link1_red.STL" />
        </geometry-->
      <origin rpy="0 0 0" xyz="0.019070 -0.014470 0.052500"/>
      <geometry>
        <box size="0.108140 0.04500 0.104000"/>
      </geometry>
    </collision>
  </link>
  <joint name="base2" type="revolute">
    <origin rpy="0 0 0" xyz="0 0 0.03105"/>
    <parent link="base2__INPUT_INTERFACE"/>
    <child link="shoulder2__INPUT_INTERFACE"/>
    <axis xyz="0 0 1"/>
    <dynamics damping=".1" friction="0.2"/>
    <limit effort="30.0" lower="-1.57075" upper="1.57075" velocity="2.208932"/>
  </joint>
  <transmission name="base2_trans">
    <type>transmission_interface/SimpleTransmission</type>
    <joint name="base2">
      <hardwareInterface>hardware_interface/EffortJointInterface</hardwareInterface>
    </joint>
    <actuator name="base2_motor">
      <hardwareInterface>hardware_interface/EffortJointInterface</hardwareInterface>
      <mechanicalReduction>300</mechanicalReduction>
    </actuator>
  </transmission>
  <link name="elbow2__INPUT_INTERFACE">
    <inertial>
      <origin rpy="0 0 0" xyz="0.27885723 0.00143862 -0.00919708"/>
      <mass value="1.58985"/>
      <inertia ixx="0.00087813" ixy="-2.653E-05" ixz="-0.00101493" iyy="0.01121522" iyz="-1.36E-05" izz="0.01137087"/>
    </inertial>
    <visual>
      <origin rpy="0 0 0" xyz="0 0 0"/>
      <geometry>
        <mesh filename="package://xMonsterCPG/meshes/M6_link2_red.STL"/>
      </geometry>
      <material name="">
        <color rgba="0.75294 0.75294 0.75294 1"/>
      </material>
    </visual>
    <collision>
      <!--origin
          xyz="0 0 0"
          rpy="0 0 0" />
        <geometry>
          <mesh
            filename="package://xMonsterCPG/meshes/boxed_meshes/link2_red.STL" />
        </geometry-->
      <origin rpy="0 0 0" xyz="0.005750 0.0 0.018750"/>
      <geometry>
        <box size="0.05950 0.04800 0.037500"/>
      </geometry>
    </collision>
    <collision>
      <origin rpy="0 1.57075 0" xyz="0.159500 0.0 0.02"/>
      <geometry>
        <cylinder length="0.246" radius="0.015811"/>
      </geometry>
    </collision>
    <collision>
      <origin rpy="0 0 0" xyz="0.317750 0.0 0.01875"/>
      <geometry>
        <box size="0.06850 0.06500 0.037500"/>
      </geometry>
    </collision>
    <collision>
      <origin rpy="0.0 0.0 0.0" xyz="0.299560 0.001750 -0.015520"/>
      <geometry>
        <box size="0.106400 0.069500 0.030050"/>
      </geometry>
    </collision>
  </link>
  <joint name="shoulder2" type="revolute">
    <origin rpy="1.57075 0 3.1415" xyz="0 0.00855 0.055"/>
    <parent link="shoulder2__INPUT_INTERFACE"/>
    <child link="elbow2__INPUT_INTERFACE"/>
    <axis xyz="0 0 1"/>
    <dynamics damping=".1" friction="0.2"/>
    <limit effort="30.0" lower="-1.57075" upper="1.57075" velocity="2.208932"/>
  </joint>
  <transmission name="shoulder2_trans">
    <type>transmission_interface/SimpleTransmission</type>
    <joint name="shoulder2">
      <hardwareInterface>hardware_interface/EffortJointInterface</hardwareInterface>
    </joint>
    <actuator name="shoulder2_motor">
      <hardwareInterface>hardware_interface/EffortJointInterface</hardwareInterface>
      <mechanicalReduction>300</mechanicalReduction>
    </actuator>
  </transmission>
  <link name="leg2__LAST_LINK">
    <inertial>
      <origin rpy="0 0 0" xyz="0.12121923 0 0.01723596"/>
      <mass value="0.229433"/>
      <inertia ixx="7.471E-05" ixy="0" ixz="7.798E-05" iyy="0.00331684" iyz="0" izz="0.0033262"/>
    </inertial>
    <visual>
      <origin rpy="0 0 0" xyz="0 0 0"/>
      <geometry>
        <mesh filename="package://xMonsterCPG/meshes/M6_link3_red.STL"/>
      </geometry>
      <material name="">
        <color rgba="0.75294 0.75294 0.75294 1"/>
      </material>
    </visual>
    <!--collision>
        <origin
          xyz="0 0 0"
          rpy="0 0 0" />
        <geometry>
          <mesh
            filename="package://xMonsterCPG/meshes/boxed_meshes/link3_red.STL" />
        </geometry>
      </collision-->
    <collision>
      <origin rpy="0 0 0" xyz="0.00575 0.0 0.0185"/>
      <geometry>
        <box size="0.05850 0.04800 0.03650"/>
      </geometry>
    </collision>
    <collision>
      <origin rpy="0.0 1.57075 0.0" xyz="0.15125 0.000 0.020"/>
      <geometry>
        <cylinder length="0.230500" radius="0.015811"/>
      </geometry>
    </collision>
    <collision>
      <origin rpy="0.0 0.0 0.0" xyz="0.28950 0.00 0.02"/>
      <geometry>
        <box size="0.045000 0.047030 0.047030"/>
      </geometry>
    </collision>
  </link>
  <joint name="elbow2" type="revolute">
    <origin rpy="3.1415 0 0" xyz="0.3195 0 -0.03105"/>
    <parent link="elbow2__INPUT_INTERFACE"/>
    <child link="leg2__LAST_LINK"/>
    <axis xyz="0 0 1"/>
    <dynamics damping=".1" friction="0.2"/>
    <limit effort="30.0" lower="-3.1415" upper="3.1415" velocity="2.208932"/>
  </joint>
  <transmission name="elbow2_trans">
    <type>transmission_interface/SimpleTransmission</type>
    <joint name="elbow2">
      <hardwareInterface>hardware_interface/EffortJointInterface</hardwareInterface>
    </joint>
    <actuator name="elbow2_motor">
      <hardwareInterface>hardware_interface/EffortJointInterface</hardwareInterface>
      <mechanicalReduction>300</mechanicalReduction>
    </actuator>
  </transmission>
  <link name="leg2__FOOT">
    <inertial>
      <origin rpy="0 0 0" xyz="0 0 0"/>
      <mass value="0"/>
      <inertia ixx="0" ixy="0" ixz="0" iyy="0" iyz="0" izz="0"/>
    </inertial>
  </link>
  <joint name="leg2__FOOT_INTERFACE" type="fixed">
    <origin rpy="0 0 0" xyz="0.31 0 0.02"/>
    <parent link="leg2__LAST_LINK"/>
    <child link="leg2__FOOT"/>
    <axis xyz="0 0 1"/>
    <limit effort="0" velocity="0"/>
  </joint>
  <link name="base4__INPUT_INTERFACE">
    <inertial>
      <origin rpy="0 0 0" xyz="0.015005 0.001775 0.015011"/>
      <mass value="1.2804"/>
      <inertia ixx="0.000533112547871023" ixy="8.52907138161489E-05" ixz="6.73224445510202E-07" iyy="0.000959826064510336" iyz="8.0840859065961E-07" izz="0.00130175668733721"/>
    </inertial>
    <visual>
      <origin rpy="0 0 0" xyz="0 0 0.015"/>
      <geometry>
        <mesh filename="package://xMonsterCPG/meshes/M6_base_motor.STL"/>
      </geometry>
      <material name="">
        <color rgba="0.79216 0.81961 0.93333 1"/>
      </material>
    </visual>
    <collision>
      <!--origin
          xyz="0 0 0.015"
          rpy="0 0 0" />
        <geometry>
          <mesh
            filename="package://xMonsterCPG/meshes/boxed_meshes/base_motor.STL" />
        </geometry-->
      <origin rpy="0 0 0" xyz="0.019940 0.001750 0.015525"/>
      <geometry>
        <box size="0.106400 0.069500 0.031050"/>
      </geometry>
    </collision>
  </link>
  <joint name="leg4__OUTPUT_INTERFACE" type="fixed">
    <origin rpy="0 0 1.57075" xyz="0 -0.1875 0"/>
    <parent link="base_link"/>
    <child link="base4__INPUT_INTERFACE"/>
    <axis xyz="0 0 1"/>
    <limit effort="0" velocity="0"/>
  </joint>
  <link name="shoulder4__INPUT_INTERFACE">
    <inertial>
      <origin rpy="0 0 0" xyz="-0.012554 -0.0090693 -0.0503697"/>
      <mass value="1.4679"/>
      <inertia ixx="0.00085304" ixy="-4.463E-05" ixz="-4.178E-05" iyy="0.0016596" iyz="-4.4E-06" izz="0.00113592"/>
    </inertial>
    <visual>
      <origin rpy="0 0 0" xyz="0 0 0"/>
      <geometry>
        <mesh filename="package://xMonsterCPG/meshes/M6_right_link1_red.STL"/>
      </geometry>
      <material name="">
        <color rgba="0.75294 0.75294 0.75294 1"/>
      </material>
    </visual>
    <collision>
      <!--origin
          xyz="0 0 0"
          rpy="0 0 0" />
        <geometry>
          <mesh
            filename="package://xMonsterCPG/meshes/boxed_meshes/right_link1_red.STL" />
        </geometry-->
      <origin rpy="0 0 0" xyz="0.019070 -0.014470 0.052500"/>
      <geometry>
        <box size="0.108140 0.04500 0.104000"/>
      </geometry>
    </collision>
  </link>
  <joint name="base4" type="revolute">
    <origin rpy="0 0 0" xyz="0 0 0.03105"/>
    <parent link="base4__INPUT_INTERFACE"/>
    <child link="shoulder4__INPUT_INTERFACE"/>
    <axis xyz="0 0 1"/>
    <dynamics damping=".1" friction="0.2"/>
    <limit effort="30.0" lower="-1.57075" upper="1.57075" velocity="2.208932"/>
  </joint>
  <transmission name="base4_trans">
    <type>transmission_interface/SimpleTransmission</type>
    <joint name="base4">
      <hardwareInterface>hardware_interface/EffortJointInterface</hardwareInterface>
    </joint>
    <actuator name="base4_motor">
      <hardwareInterface>hardware_interface/EffortJointInterface</hardwareInterface>
      <mechanicalReduction>300</mechanicalReduction>
    </actuator>
  </transmission>
  <link name="elbow4__INPUT_INTERFACE">
    <inertial>
      <origin rpy="0 0 0" xyz="0.27885723 0.00143862 -0.00919708"/>
      <mass value="1.58985"/>
      <inertia ixx="0.00087813" ixy="-2.653E-05" ixz="-0.00101493" iyy="0.01121522" iyz="-1.36E-05" izz="0.01137087"/>
    </inertial>
    <visual>
      <origin rpy="0 0 0" xyz="0 0 0"/>
      <geometry>
        <mesh filename="package://xMonsterCPG/meshes/M6_link2_red.STL"/>
      </geometry>
      <material name="">
        <color rgba="0.75294 0.75294 0.75294 1"/>
      </material>
    </visual>
    <collision>
      <!--origin
          xyz="0 0 0"
          rpy="0 0 0" />
        <geometry>
          <mesh
            filename="package://xMonsterCPG/meshes/boxed_meshes/link2_red.STL" />
        </geometry-->
      <origin rpy="0 0 0" xyz="0.005750 0.0 0.018750"/>
      <geometry>
        <box size="0.05950 0.04800 0.037500"/>
      </geometry>
    </collision>
    <collision>
      <origin rpy="0 1.57075 0" xyz="0.159500 0.0 0.02"/>
      <geometry>
        <cylinder length="0.246" radius="0.015811"/>
      </geometry>
    </collision>
    <collision>
      <origin rpy="0 0 0" xyz="0.317750 0.0 0.01875"/>
      <geometry>
        <box size="0.06850 0.06500 0.037500"/>
      </geometry>
    </collision>
    <collision>
      <origin rpy="0.0 0.0 0.0" xyz="0.299560 0.001750 -0.015520"/>
      <geometry>
        <box size="0.106400 0.069500 0.030050"/>
      </geometry>
    </collision>
  </link>
  <joint name="shoulder4" type="revolute">
    <origin rpy="1.57075 0 3.1415" xyz="0 0.00855 0.055"/>
    <parent link="shoulder4__INPUT_INTERFACE"/>
    <child link="elbow4__INPUT_INTERFACE"/>
    <axis xyz="0 0 1"/>
    <dynamics damping=".1" friction="0.2"/>
    <limit effort="30.0" lower="-1.57075" upper="1.57075" velocity="2.208932"/>
  </joint>
  <transmission name="shoulder4_trans">
    <type>transmission_interface/SimpleTransmission</type>
    <joint name="shoulder4">
      <hardwareInterface>hardware_interface/EffortJointInterface</hardwareInterface>
    </joint>
    <actuator name="shoulder4_motor">
      <hardwareInterface>hardware_interface/EffortJointInterface</hardwareInterface>
      <mechanicalReduction>300</mechanicalReduction>
    </actuator>
  </transmission>
  <link name="leg4__LAST_LINK">
    <inertial>
      <origin rpy="0 0 0" xyz="0.12121923 0 0.01723596"/>
      <mass value="0.229433"/>
      <inertia ixx="7.471E-05" ixy="0" ixz="7.798E-05" iyy="0.00331684" iyz="0" izz="0.0033262"/>
    </inertial>
    <visual>
      <origin rpy="0 0 0" xyz="0 0 0"/>
      <geometry>
        <mesh filename="package://xMonsterCPG/meshes/M6_link3_red.STL"/>
      </geometry>
      <material name="">
        <color rgba="0.75294 0.75294 0.75294 1"/>
      </material>
    </visual>
    <!--collision>
        <origin
          xyz="0 0 0"
          rpy="0 0 0" />
        <geometry>
          <mesh
            filename="package://xMonsterCPG/meshes/boxed_meshes/link3_red.STL" />
        </geometry>
      </collision-->
    <collision>
      <origin rpy="0 0 0" xyz="0.00575 0.0 0.0185"/>
      <geometry>
        <box size="0.05850 0.04800 0.03650"/>
      </geometry>
    </collision>
    <collision>
      <origin rpy="0.0 1.57075 0.0" xyz="0.15125 0.000 0.020"/>
      <geometry>
        <cylinder length="0.230500" radius="0.015811"/>
      </geometry>
    </collision>
    <collision>
      <origin rpy="0.0 0.0 0.0" xyz="0.28950 0.00 0.02"/>
      <geometry>
        <box size="0.045000 0.047030 0.047030"/>
      </geometry>
    </collision>
  </link>
  <joint name="elbow4" type="revolute">
    <origin rpy="3.1415 0 0" xyz="0.3195 0 -0.03105"/>
    <parent link="elbow4__INPUT_INTERFACE"/>
    <child link="leg4__LAST_LINK"/>
    <axis xyz="0 0 1"/>
    <dynamics damping=".1" friction="0.2"/>
    <limit effort="30.0" lower="-3.1415" upper="3.1415" velocity="2.208932"/>
  </joint>
  <transmission name="elbow4_trans">
    <type>transmission_interface/SimpleTransmission</type>
    <joint name="elbow4">
      <hardwareInterface>hardware_interface/EffortJointInterface</hardwareInterface>
    </joint>
    <actuator name="elbow4_motor">
      <hardwareInterface>hardware_interface/EffortJointInterface</hardwareInterface>
      <mechanicalReduction>300</mechanicalReduction>
    </actuator>
  </transmission>
  <link name="leg4__FOOT">
    <inertial>
      <origin rpy="0 0 0" xyz="0 0 0"/>
      <mass value="0"/>
      <inertia ixx="0" ixy="0" ixz="0" iyy="0" iyz="0" izz="0"/>
    </inertial>
  </link>
  <joint name="leg4__FOOT_INTERFACE" type="fixed">
    <origin rpy="0 0 0" xyz="0.31 0 0.02"/>
    <parent link="leg4__LAST_LINK"/>
    <child link="leg4__FOOT"/>
    <axis xyz="0 0 1"/>
    <limit effort="0" velocity="0"/>
  </joint>
  <link name="base6__INPUT_INTERFACE">
    <inertial>
      <origin rpy="0 0 0" xyz="0.015005 0.001775 0.015011"/>
      <mass value="1.2804"/>
      <inertia ixx="0.000533112547871023" ixy="8.52907138161489E-05" ixz="6.73224445510202E-07" iyy="0.000959826064510336" iyz="8.0840859065961E-07" izz="0.00130175668733721"/>
    </inertial>
    <visual>
      <origin rpy="0 0 0" xyz="0 0 0.015"/>
      <geometry>
        <mesh filename="package://xMonsterCPG/meshes/M6_base_motor.STL"/>
      </geometry>
      <material name="">
        <color rgba="0.79216 0.81961 0.93333 1"/>
      </material>
    </visual>
    <collision>
      <!--origin
          xyz="0 0 0.015"
          rpy="0 0 0" />
        <geometry>
          <mesh
            filename="package://xMonsterCPG/meshes/boxed_meshes/base_motor.STL" />
        </geometry-->
      <origin rpy="0 0 0" xyz="0.019940 0.001750 0.015525"/>
      <geometry>
        <box size="0.106400 0.069500 0.031050"/>
      </geometry>
    </collision>
  </link>
  <joint name="leg6__OUTPUT_INTERFACE" type="fixed">
    <origin rpy="0 0 0.523583333333" xyz="-0.205681 -0.11875 0"/>
    <parent link="base_link"/>
    <child link="base6__INPUT_INTERFACE"/>
    <axis xyz="0 0 1"/>
    <limit effort="0" velocity="0"/>
  </joint>
  <link name="shoulder6__INPUT_INTERFACE">
    <inertial>
      <origin rpy="0 0 0" xyz="-0.012554 -0.0090693 -0.0503697"/>
      <mass value="1.4679"/>
      <inertia ixx="0.00085304" ixy="-4.463E-05" ixz="-4.178E-05" iyy="0.0016596" iyz="-4.4E-06" izz="0.00113592"/>
    </inertial>
    <visual>
      <origin rpy="0 0 0" xyz="0 0 0"/>
      <geometry>
        <mesh filename="package://xMonsterCPG/meshes/M6_right_link1_red.STL"/>
      </geometry>
      <material name="">
        <color rgba="0.75294 0.75294 0.75294 1"/>
      </material>
    </visual>
    <collision>
      <!--origin
          xyz="0 0 0"
          rpy="0 0 0" />
        <geometry>
          <mesh
            filename="package://xMonsterCPG/meshes/boxed_meshes/right_link1_red.STL" />
        </geometry-->
      <origin rpy="0 0 0" xyz="0.019070 -0.014470 0.052500"/>
      <geometry>
        <box size="0.108140 0.04500 0.104000"/>
      </geometry>
    </collision>
  </link>
  <joint name="base6" type="revolute">
    <origin rpy="0 0 0" xyz="0 0 0.03105"/>
    <parent link="base6__INPUT_INTERFACE"/>
    <child link="shoulder6__INPUT_INTERFACE"/>
    <axis xyz="0 0 1"/>
    <dynamics damping=".1" friction="0.2"/>
    <limit effort="30.0" lower="-1.57075" upper="1.57075" velocity="2.208932"/>
  </joint>
  <transmission name="base6_trans">
    <type>transmission_interface/SimpleTransmission</type>
    <joint name="base6">
      <hardwareInterface>hardware_interface/EffortJointInterface</hardwareInterface>
    </joint>
    <actuator name="base6_motor">
      <hardwareInterface>hardware_interface/EffortJointInterface</hardwareInterface>
      <mechanicalReduction>300</mechanicalReduction>
    </actuator>
  </transmission>
  <link name="elbow6__INPUT_INTERFACE">
    <inertial>
      <origin rpy="0 0 0" xyz="0.27885723 0.00143862 -0.00919708"/>
      <mass value="1.58985"/>
      <inertia ixx="0.00087813" ixy="-2.653E-05" ixz="-0.00101493" iyy="0.01121522" iyz="-1.36E-05" izz="0.01137087"/>
    </inertial>
    <visual>
      <origin rpy="0 0 0" xyz="0 0 0"/>
      <geometry>
        <mesh filename="package://xMonsterCPG/meshes/M6_link2_red.STL"/>
      </geometry>
      <material name="">
        <color rgba="0.75294 0.75294 0.75294 1"/>
      </material>
    </visual>
    <collision>
      <!--origin
          xyz="0 0 0"
          rpy="0 0 0" />
        <geometry>
          <mesh
            filename="package://xMonsterCPG/meshes/boxed_meshes/link2_red.STL" />
        </geometry-->
      <origin rpy="0 0 0" xyz="0.005750 0.0 0.018750"/>
      <geometry>
        <box size="0.05950 0.04800 0.037500"/>
      </geometry>
    </collision>
    <collision>
      <origin rpy="0 1.57075 0" xyz="0.159500 0.0 0.02"/>
      <geometry>
        <cylinder length="0.246" radius="0.015811"/>
      </geometry>
    </collision>
    <collision>
      <origin rpy="0 0 0" xyz="0.317750 0.0 0.01875"/>
      <geometry>
        <box size="0.06850 0.06500 0.037500"/>
      </geometry>
    </collision>
    <collision>
      <origin rpy="0.0 0.0 0.0" xyz="0.299560 0.001750 -0.015520"/>
      <geometry>
        <box size="0.106400 0.069500 0.030050"/>
      </geometry>
    </collision>
  </link>
  <joint name="shoulder6" type="revolute">
    <origin rpy="1.57075 0 3.1415" xyz="0 0.00855 0.055"/>
    <parent link="shoulder6__INPUT_INTERFACE"/>
    <child link="elbow6__INPUT_INTERFACE"/>
    <axis xyz="0 0 1"/>
    <dynamics damping=".1" friction="0.2"/>
    <limit effort="30.0" lower="-1.57075" upper="1.57075" velocity="2.208932"/>
  </joint>
  <transmission name="shoulder6_trans">
    <type>transmission_interface/SimpleTransmission</type>
    <joint name="shoulder6">
      <hardwareInterface>hardware_interface/EffortJointInterface</hardwareInterface>
    </joint>
    <actuator name="shoulder6_motor">
      <hardwareInterface>hardware_interface/EffortJointInterface</hardwareInterface>
      <mechanicalReduction>300</mechanicalReduction>
    </actuator>
  </transmission>
  <link name="leg6__LAST_LINK">
    <inertial>
      <origin rpy="0 0 0" xyz="0.12121923 0 0.01723596"/>
      <mass value="0.229433"/>
      <inertia ixx="7.471E-05" ixy="0" ixz="7.798E-05" iyy="0.00331684" iyz="0" izz="0.0033262"/>
    </inertial>
    <visual>
      <origin rpy="0 0 0" xyz="0 0 0"/>
      <geometry>
        <mesh filename="package://xMonsterCPG/meshes/M6_link3_red.STL"/>
      </geometry>
      <material name="">
        <color rgba="0.75294 0.75294 0.75294 1"/>
      </material>
    </visual>
    <!--collision>
        <origin
          xyz="0 0 0"
          rpy="0 0 0" />
        <geometry>
          <mesh
            filename="package://xMonsterCPG/meshes/boxed_meshes/link3_red.STL" />
        </geometry>
      </collision-->
    <collision>
      <origin rpy="0 0 0" xyz="0.00575 0.0 0.0185"/>
      <geometry>
        <box size="0.05850 0.04800 0.03650"/>
      </geometry>
    </collision>
    <collision>
      <origin rpy="0.0 1.57075 0.0" xyz="0.15125 0.000 0.020"/>
      <geometry>
        <cylinder length="0.230500" radius="0.015811"/>
      </geometry>
    </collision>
    <collision>
      <origin rpy="0.0 0.0 0.0" xyz="0.28950 0.00 0.02"/>
      <geometry>
        <box size="0.045000 0.047030 0.047030"/>
      </geometry>
    </collision>
  </link>
  <joint name="elbow6" type="revolute">
    <origin rpy="3.1415 0 0" xyz="0.3195 0 -0.03105"/>
    <parent link="elbow6__INPUT_INTERFACE"/>
    <child link="leg6__LAST_LINK"/>
    <axis xyz="0 0 1"/>
    <dynamics damping=".1" friction="0.2"/>
    <limit effort="30.0" lower="-3.1415" upper="3.1415" velocity="2.208932"/>
  </joint>
  <transmission name="elbow6_trans">
    <type>transmission_interface/SimpleTransmission</type>
    <joint name="elbow6">
      <hardwareInterface>hardware_interface/EffortJointInterface</hardwareInterface>
    </joint>
    <actuator name="elbow6_motor">
      <hardwareInterface>hardware_interface/EffortJointInterface</hardwareInterface>
      <mechanicalReduction>300</mechanicalReduction>
    </actuator>
  </transmission>
  <link name="leg6__FOOT">
    <inertial>
      <origin rpy="0 0 0" xyz="0 0 0"/>
      <mass value="0"/>
      <inertia ixx="0" ixy="0" ixz="0" iyy="0" iyz="0" izz="0"/>
    </inertial>
  </link>
  <joint name="leg6__FOOT_INTERFACE" type="fixed">
    <origin rpy="0 0 0" xyz="0.31 0 0.02"/>
    <parent link="leg6__LAST_LINK"/>
    <child link="leg6__FOOT"/>
    <axis xyz="0 0 1"/>
    <limit effort="0" velocity="0"/>
  </joint>
  <!-- ros_control plugin -->
  <gazebo>
    <plugin filename="libgazebo_ros_control.so" name="gazebo_ros_control">
      <robotNamespace>/m6</robotNamespace>
      <robotSimType>gazebo_ros_control/DefaultRobotHWSim</robotSimType>
      <legacyModeNS>true</legacyModeNS>
    </plugin>
  </gazebo>
  <gazebo reference="base_link">
    <material>Gazebo/Grey</material>
  </gazebo>
  <gazebo reference="r_foot">
    <mu1>1.5</mu1>
    <mu2>1.5</mu2>
  </gazebo>
  <gazebo reference="base1__INPUT_INTERFACE">
    <material>Gazebo/Red</material>
    <static>false</static>
    <selfCollide>true</selfCollide>
  </gazebo>
  <gazebo reference="shoulder1__INPUT_INTERFACE">
    <material>Gazebo/Black</material>
    <static>false</static>
    <selfCollide>true</selfCollide>
  </gazebo>
  <gazebo reference="elbow1__INPUT_INTERFACE">
    <static>false</static>
    <selfCollide>true</selfCollide>
  </gazebo>
  <gazebo reference="leg1__LAST_LINK">
    <material>Gazebo/Grey</material>
    <mu1>1000000000000000</mu1>
    <mu2>1000000000</mu2>
    <static>false</static>
    <selfCollide>true</selfCollide>
  </gazebo>
  <gazebo reference="leg1__FOOT">
    <material>Gazebo/Grey</material>
    <mu1>100000000000</mu1>
    <mu2>100000000000000</mu2>
    <static>false</static>
    <selfCollide>true</selfCollide>
  </gazebo>
  <gazebo reference="base2__INPUT_INTERFACE">
    <material>Gazebo/Red</material>
    <static>false</static>
    <selfCollide>true</selfCollide>
  </gazebo>
  <gazebo reference="shoulder2__INPUT_INTERFACE">
    <material>Gazebo/Black</material>
    <static>false</static>
    <selfCollide>true</selfCollide>
  </gazebo>
  <gazebo reference="elbow2__INPUT_INTERFACE">
    <static>false</static>
    <selfCollide>true</selfCollide>
  </gazebo>
  <gazebo reference="leg2__LAST_LINK">
    <material>Gazebo/Grey</material>
    <mu1>1000000000000000</mu1>
    <mu2>1000000000</mu2>
    <static>false</static>
    <selfCollide>true</selfCollide>
  </gazebo>
  <gazebo reference="leg2__FOOT">
    <material>Gazebo/Grey</material>
    <mu1>100000000000</mu1>
    <mu2>100000000000000</mu2>
    <static>false</static>
    <selfCollide>true</selfCollide>
  </gazebo>
  <gazebo reference="base3__INPUT_INTERFACE">
    <material>Gazebo/Red</material>
    <static>false</static>
    <selfCollide>true</selfCollide>
  </gazebo>
  <gazebo reference="shoulder3__INPUT_INTERFACE">
    <material>Gazebo/Black</material>
    <static>false</static>
    <selfCollide>true</selfCollide>
  </gazebo>
  <gazebo reference="elbow3__INPUT_INTERFACE">
    <static>false</static>
    <selfCollide>true</selfCollide>
  </gazebo>
  <gazebo reference="leg3__LAST_LINK">
    <material>Gazebo/Grey</material>
    <mu1>1000000000000000</mu1>
    <mu2>1000000000</mu2>
    <static>false</static>
    <selfCollide>true</selfCollide>
  </gazebo>
  <gazebo reference="leg3__FOOT">
    <material>Gazebo/Grey</material>
    <mu1>100000000000</mu1>
    <mu2>100000000000000</mu2>
    <static>false</static>
    <selfCollide>true</selfCollide>
  </gazebo>
  <gazebo reference="base4__INPUT_INTERFACE">
    <material>Gazebo/Red</material>
    <static>false</static>
    <selfCollide>true</selfCollide>
  </gazebo>
  <gazebo reference="shoulder4__INPUT_INTERFACE">
    <material>Gazebo/Black</material>
    <static>false</static>
    <selfCollide>true</selfCollide>
  </gazebo>
  <gazebo reference="elbow4__INPUT_INTERFACE">
    <static>false</static>
    <selfCollide>true</selfCollide>
  </gazebo>
  <gazebo reference="leg4__LAST_LINK">
    <material>Gazebo/Grey</material>
    <mu1>1000000000000000</mu1>
    <mu2>1000000000</mu2>
    <static>false</static>
    <selfCollide>true</selfCollide>
  </gazebo>
  <gazebo reference="leg4__FOOT">
    <material>Gazebo/Grey</material>
    <mu1>100000000000</mu1>
    <mu2>100000000000000</mu2>
    <static>false</static>
    <selfCollide>true</selfCollide>
  </gazebo>
  <gazebo reference="base5__INPUT_INTERFACE">
    <material>Gazebo/Red</material>
    <static>false</static>
    <selfCollide>true</selfCollide>
  </gazebo>
  <gazebo reference="shoulder5__INPUT_INTERFACE">
    <material>Gazebo/Black</material>
    <static>false</static>
    <selfCollide>true</selfCollide>
  </gazebo>
  <gazebo reference="elbow5__INPUT_INTERFACE">
    <static>false</static>
    <selfCollide>true</selfCollide>
  </gazebo>
  <gazebo reference="leg5__LAST_LINK">
    <material>Gazebo/Grey</material>
    <mu1>1000000000000000</mu1>
    <mu2>1000000000</mu2>
    <static>false</static>
    <selfCollide>true</selfCollide>
  </gazebo>
  <gazebo reference="leg5__FOOT">
    <material>Gazebo/Grey</material>
    <mu1>100000000000</mu1>
    <mu2>100000000000000</mu2>
    <static>false</static>
    <selfCollide>true</selfCollide>
  </gazebo>
  <gazebo reference="base6__INPUT_INTERFACE">
    <material>Gazebo/Red</material>
    <static>false</static>
    <selfCollide>true</selfCollide>
  </gazebo>
  <gazebo reference="shoulder6__INPUT_INTERFACE">
    <material>Gazebo/Black</material>
    <static>false</static>
    <selfCollide>true</selfCollide>
  </gazebo>
  <gazebo reference="elbow6__INPUT_INTERFACE">
    <static>false</static>
    <selfCollide>true</selfCollide>
  </gazebo>
  <gazebo reference="leg6__LAST_LINK">
    <material>Gazebo/Grey</material>
    <mu1>1000000000000000</mu1>
    <mu2>1000000000</mu2>
    <static>false</static>
    <selfCollide>true</selfCollide>
  </gazebo>
  <gazebo reference="leg6__FOOT">
    <material>Gazebo/Grey</material>
    <mu1>100000000000</mu1>
    <mu2>100000000000000</mu2>
    <static>false</static>
    <selfCollide>true</selfCollide>
  </gazebo>
  <gazebo reference="base1">
    <provideFeedback>true</provideFeedback>
  </gazebo>
  <!-- joint_torque_sensor plugin -->
  <gazebo>
    <plugin filename="libgazebo_ros_ft_sensor.so" name="base1_ros_ft_sensor">
      <robotNamespace>/m6</robotNamespace>
      <updateRate>250.0</updateRate>
      <gaussianNoise>0.025</gaussianNoise>
      <topicName>sensors/base1/torque</topicName>
      <jointName>base1</jointName>
    </plugin>
  </gazebo>
  <gazebo reference="shoulder1">
    <provideFeedback>true</provideFeedback>
  </gazebo>
  <!-- joint_torque_sensor plugin -->
  <gazebo>
    <plugin filename="libgazebo_ros_ft_sensor.so" name="shoulder1_ros_ft_sensor">
      <robotNamespace>/m6</robotNamespace>
      <updateRate>250.0</updateRate>
      <gaussianNoise>0.025</gaussianNoise>
      <topicName>sensors/shoulder1/torque</topicName>
      <jointName>shoulder1</jointName>
    </plugin>
  </gazebo>
  <gazebo reference="elbow1">
    <provideFeedback>true</provideFeedback>
  </gazebo>
  <!-- joint_torque_sensor plugin -->
  <gazebo>
    <plugin filename="libgazebo_ros_ft_sensor.so" name="elbow1_ros_ft_sensor">
      <robotNamespace>/m6</robotNamespace>
      <updateRate>250.0</updateRate>
      <gaussianNoise>0.025</gaussianNoise>
      <topicName>sensors/elbow1/torque</topicName>
      <jointName>elbow1</jointName>
    </plugin>
  </gazebo>
  <gazebo reference="base2">
    <provideFeedback>true</provideFeedback>
  </gazebo>
  <!-- joint_torque_sensor plugin -->
  <gazebo>
    <plugin filename="libgazebo_ros_ft_sensor.so" name="base2_ros_ft_sensor">
      <robotNamespace>/m6</robotNamespace>
      <updateRate>250.0</updateRate>
      <gaussianNoise>0.025</gaussianNoise>
      <topicName>sensors/base2/torque</topicName>
      <jointName>base2</jointName>
    </plugin>
  </gazebo>
  <gazebo reference="shoulder2">
    <provideFeedback>true</provideFeedback>
  </gazebo>
  <!-- joint_torque_sensor plugin -->
  <gazebo>
    <plugin filename="libgazebo_ros_ft_sensor.so" name="shoulder2_ros_ft_sensor">
      <robotNamespace>/m6</robotNamespace>
      <updateRate>250.0</updateRate>
      <gaussianNoise>0.025</gaussianNoise>
      <topicName>sensors/shoulder2/torque</topicName>
      <jointName>shoulder2</jointName>
    </plugin>
  </gazebo>
  <gazebo reference="elbow2">
    <provideFeedback>true</provideFeedback>
  </gazebo>
  <!-- joint_torque_sensor plugin -->
  <gazebo>
    <plugin filename="libgazebo_ros_ft_sensor.so" name="elbow2_ros_ft_sensor">
      <robotNamespace>/m6</robotNamespace>
      <updateRate>250.0</updateRate>
      <gaussianNoise>0.025</gaussianNoise>
      <topicName>sensors/elbow2/torque</topicName>
      <jointName>elbow2</jointName>
    </plugin>
  </gazebo>
  <gazebo reference="base3">
    <provideFeedback>true</provideFeedback>
  </gazebo>
  <!-- joint_torque_sensor plugin -->
  <gazebo>
    <plugin filename="libgazebo_ros_ft_sensor.so" name="base3_ros_ft_sensor">
      <robotNamespace>/m6</robotNamespace>
      <updateRate>250.0</updateRate>
      <gaussianNoise>0.025</gaussianNoise>
      <topicName>sensors/base3/torque</topicName>
      <jointName>base3</jointName>
    </plugin>
  </gazebo>
  <gazebo reference="shoulder3">
    <provideFeedback>true</provideFeedback>
  </gazebo>
  <!-- joint_torque_sensor plugin -->
  <gazebo>
    <plugin filename="libgazebo_ros_ft_sensor.so" name="shoulder3_ros_ft_sensor">
      <robotNamespace>/m6</robotNamespace>
      <updateRate>250.0</updateRate>
      <gaussianNoise>0.025</gaussianNoise>
      <topicName>sensors/shoulder3/torque</topicName>
      <jointName>shoulder3</jointName>
    </plugin>
  </gazebo>
  <gazebo reference="elbow3">
    <provideFeedback>true</provideFeedback>
  </gazebo>
  <!-- joint_torque_sensor plugin -->
  <gazebo>
    <plugin filename="libgazebo_ros_ft_sensor.so" name="elbow3_ros_ft_sensor">
      <robotNamespace>/m6</robotNamespace>
      <updateRate>250.0</updateRate>
      <gaussianNoise>0.025</gaussianNoise>
      <topicName>sensors/elbow3/torque</topicName>
      <jointName>elbow3</jointName>
    </plugin>
  </gazebo>
  <gazebo reference="base4">
    <provideFeedback>true</provideFeedback>
  </gazebo>
  <!-- joint_torque_sensor plugin -->
  <gazebo>
    <plugin filename="libgazebo_ros_ft_sensor.so" name="base4_ros_ft_sensor">
      <robotNamespace>/m6</robotNamespace>
      <updateRate>250.0</updateRate>
      <gaussianNoise>0.025</gaussianNoise>
      <topicName>sensors/base4/torque</topicName>
      <jointName>base4</jointName>
    </plugin>
  </gazebo>
  <gazebo reference="shoulder4">
    <provideFeedback>true</provideFeedback>
  </gazebo>
  <!-- joint_torque_sensor plugin -->
  <gazebo>
    <plugin filename="libgazebo_ros_ft_sensor.so" name="shoulder4_ros_ft_sensor">
      <robotNamespace>/m6</robotNamespace>
      <updateRate>250.0</updateRate>
      <gaussianNoise>0.025</gaussianNoise>
      <topicName>sensors/shoulder4/torque</topicName>
      <jointName>shoulder4</jointName>
    </plugin>
  </gazebo>
  <gazebo reference="elbow4">
    <provideFeedback>true</provideFeedback>
  </gazebo>
  <!-- joint_torque_sensor plugin -->
  <gazebo>
    <plugin filename="libgazebo_ros_ft_sensor.so" name="elbow4_ros_ft_sensor">
      <robotNamespace>/m6</robotNamespace>
      <updateRate>250.0</updateRate>
      <gaussianNoise>0.025</gaussianNoise>
      <topicName>sensors/elbow4/torque</topicName>
      <jointName>elbow4</jointName>
    </plugin>
  </gazebo>
  <gazebo reference="base5">
    <provideFeedback>true</provideFeedback>
  </gazebo>
  <!-- joint_torque_sensor plugin -->
  <gazebo>
    <plugin filename="libgazebo_ros_ft_sensor.so" name="base5_ros_ft_sensor">
      <robotNamespace>/m6</robotNamespace>
      <updateRate>250.0</updateRate>
      <gaussianNoise>0.025</gaussianNoise>
      <topicName>sensors/base5/torque</topicName>
      <jointName>base5</jointName>
    </plugin>
  </gazebo>
  <gazebo reference="shoulder5">
    <provideFeedback>true</provideFeedback>
  </gazebo>
  <!-- joint_torque_sensor plugin -->
  <gazebo>
    <plugin filename="libgazebo_ros_ft_sensor.so" name="shoulder5_ros_ft_sensor">
      <robotNamespace>/m6</robotNamespace>
      <updateRate>250.0</updateRate>
      <gaussianNoise>0.025</gaussianNoise>
      <topicName>sensors/shoulder5/torque</topicName>
      <jointName>shoulder5</jointName>
    </plugin>
  </gazebo>
  <gazebo reference="elbow5">
    <provideFeedback>true</provideFeedback>
  </gazebo>
  <!-- joint_torque_sensor plugin -->
  <gazebo>
    <plugin filename="libgazebo_ros_ft_sensor.so" name="elbow5_ros_ft_sensor">
      <robotNamespace>/m6</robotNamespace>
      <updateRate>250.0</updateRate>
      <gaussianNoise>0.025</gaussianNoise>
      <topicName>sensors/elbow5/torque</topicName>
      <jointName>elbow5</jointName>
    </plugin>
  </gazebo>
  <gazebo reference="base6">
    <provideFeedback>true</provideFeedback>
  </gazebo>
  <!-- joint_torque_sensor plugin -->
  <gazebo>
    <plugin filename="libgazebo_ros_ft_sensor.so" name="base6_ros_ft_sensor">
      <robotNamespace>/m6</robotNamespace>
      <updateRate>250.0</updateRate>
      <gaussianNoise>0.025</gaussianNoise>
      <topicName>sensors/base6/torque</topicName>
      <jointName>base6</jointName>
    </plugin>
  </gazebo>
  <gazebo reference="shoulder6">
    <provideFeedback>true</provideFeedback>
  </gazebo>
  <!-- joint_torque_sensor plugin -->
  <gazebo>
    <plugin filename="libgazebo_ros_ft_sensor.so" name="shoulder6_ros_ft_sensor">
      <robotNamespace>/m6</robotNamespace>
      <updateRate>250.0</updateRate>
      <gaussianNoise>0.025</gaussianNoise>
      <topicName>sensors/shoulder6/torque</topicName>
      <jointName>shoulder6</jointName>
    </plugin>
  </gazebo>
  <gazebo reference="elbow6">
    <provideFeedback>true</provideFeedback>
  </gazebo>
  <!-- joint_torque_sensor plugin -->
  <gazebo>
    <plugin filename="libgazebo_ros_ft_sensor.so" name="elbow6_ros_ft_sensor">
      <robotNamespace>/m6</robotNamespace>
      <updateRate>250.0</updateRate>
      <gaussianNoise>0.025</gaussianNoise>
      <topicName>sensors/elbow6/torque</topicName>
      <jointName>elbow6</jointName>
    </plugin>
  </gazebo>
  <gazebo>
    <plugin filename="libgazebo_ros_p3d.so" name="p3d">
      <alwaysOn>true</alwaysOn>
      <updateRate>1000.0</updateRate>
      <bodyName>base_link</bodyName>
      <topicName>nav_msgs</topicName>
      <frameName>world</frameName>
      <xyzOffsets>0 0 0.0</xyzOffsets>
      <rpyOffsets>0 0 0.0</rpyOffsets>
    </plugin>
  </gazebo>
</robot>

